Workbook

Sheet Inicio
A1: CENTRO NORTE · CMS EXCEL
A4: Flujo de actualización
A6: 1 | B6: Edita | C6: Ubicaciones | D6: Datos estables, coordenadas y formato
A7: 2 | B7: Actualiza | C7: Indicadores | D7: Métricas del corte; conserva el CC
A8: 3 | B8: Revisa | C8: Validacion | D8: Confirma que todos los controles indiquen OK
A9: 4 | B9: Carga | C9: Administrar | D9: Sube este .xlsx; Python valida, respalda y actualiza JSON
A11: Resumen conectado a las hojas editables
A13: Indicador | B13: Valor
A14: Tiendas capturadas | B14: =COUNTA(Ubicaciones!$A$2:$A$501) -> 72
A15: Tiendas activas | B15: =COUNTIF(Ubicaciones!$L$2:$L$501,"Sí") -> 72
A16: Filas de indicadores | B16: =COUNTA(Indicadores!$A$2:$A$501) -> 72
A18: Regla clave: CC es el identificador único y debe existir una sola vez en Ubicaciones y una sola vez en Indicadores. No cambies los encabezados de las tablas.

Sheet Ubicaciones
A1: CC | B1: Nombre Tienda | C1: DM | D1: Fecha Apertura | E1: Municipio | F1: Cobertura | G1: Formato | H1: Formato Comercial | I1: Tier | J1: Latitud | K1: Longitud | L1: Activa
A2: 38401 | B2: Coacalco | C2: Enrique César | D2: 40528.75 | E2: Coacalco De Berriozábal | F2: Estado De México | G2: Cafe | H2: Hypermarket | I2: C2 | J2: 19.628727 | K2: -99.124104 | L2: Sí
A3: 38604 | B3: Cosmopol | C3: Enrique César | D3: 42257.708 | E3: Coacalco De Berriozábal | F3: Estado De México | G3: Kiosko | H3: Mall | I3: C1 | J3: 19.632056 | K3: -99.125781 | L3: Sí
A4: 43193 | B4: Cosmopol N1 | C4: Enrique César | D4: 46007.75 | E4: Coacalco De Berriozábal | F4: Estado De México | G4: Kiosko | H4: Mall | I4: C1 | J4: 19.632072 | K4: -99.124419 | L4: Sí
A5: 38333 | B5: Izcalli Mega | C5: Enrique César | D5: 39688.708 | E5: Cuatitlan Izcalli | F5: Estado De México | G5: Cafe | H5: Hypermarket | I5: C2 | J5: 19.646978 | K5: -99.207152 | L5: Sí
A6: 38368 | B6: Luna Park | C6: Enrique César | D6: 40145.75 | E6: Cuatitlan Izcalli | F6: Estado De México | G6: Kiosko | H6: Mall | I6: C2 | J6: 19.65741 | K6: -99.210264 | L6: Sí
A7: 38515 | B7: Patio Ecatepec | C7: Enrique César | D7: 41544.708 | E7: Ecatepec De Morelos | F7: Estado De México | G7: Cafe | H7: Hypermarket | I7: C2 | J7: 19.606305 | K7: -99.045967 | L7: Sí
A8: 38456 | B8: Plaza las Flores | C8: Enrique César | D8: 41081.708 | E8: Coacalco De Berriozábal | F8: Estado De México | G8: Kiosko | H8: Hypermarket | I8: C2 | J8: 19.636402 | K8: -99.096088 | L8: Sí
A9: 38339 | B9: San Marcos | C9: Enrique César | D9: 39718.708 | E9: Cuatitlan Izcalli | F9: Estado De México | G9: Cafe | H9: Hypermarket | I9: C2 | J9: 19.670907 | K9: -99.203156 | L9: Sí
A10: 38862 | B10: San Miguel Izcalli | C10: Enrique César | D10: 43530.75 | E10: Cuatitlan Izcalli | F10: Estado De México | G10: Cafe | H10: Hypermarket | I10: C2 | J10: 19.688367 | K10: -99.214006 | L10: Sí
A11: 38186 | B11: Arboledas | C11: Nancy Rodríguez | D11: 38854.708 | E11: Atizapan De Zaragoza | F11: Estado De México | G11: Cafe | H11: Neighborhood | I11: C1 | J11: 19.559957 | K11: -99.220142 | L11: Sí
A12: 38894 | B12: Galerias Perinorte | C12: Enrique César | D12: 44182.75 | E12: Cuatitlan Izcalli | F12: Estado De México | G12: Cafe | H12: Mall | I12: C1 | J12: 19.602237 | K12: -99.19097 | L12: Sí
A13: 38230 | B13: ITEMS Edo de Mexico | C13: Nancy Rodríguez | D13: 39209.708 | E13: Atizapan De Zaragoza | F13: Estado De México | G13: Cafe | H13: Education | I13: C1 | J13: 19.59796 | K13: -99.226456 | L13: Sí
... A73: 38142 | B73: Zona Esmeralda | C73: Yazmin García | D73: 38338.75 | E73: Atizapan De Zaragoza | F73: Estado De México | G73: Cafe | H73: Shopping Center | I73: C2 | J73: 19.559076 | K73: -99.296831 | L73: Sí

Sheet Indicadores
A1: CC | B1: Corte YTD | C1: Rolling | D1: TPLH | E1: IPLH | F1: Labor | G1: Dif Labor | H1: Ventas MXN | I1: Dif Ppto | J1: OMT | K1: NPS | L1: Conexión | M1: Bebida | N1: CTC | O1: Costo | P1: Dif Costo | Q1: EBITDA | R1: Dif EBITDA | S1: DT Time | T1: Tiempo DT AA
A2: 38115 | B2: 46142.75 | C2: 0.701 | D2: 5.6 | E2: 12.7 | F2: 0.205 | G2: 0.032 | H2: 3700000 | I2: -0.124 | J2: -25.7 | K2: 61.4 | L2: 0.538 | M2: 0.59 | N2: 0.119 | O2: 0.396 | P2: 0.019 | Q2: 0.121 | R2: -0.043
A3: 38117 | B3: 46142.75 | C3: 0.399 | D3: 4.6 | E3: 10.6 | F3: 0.297 | G3: 0.112 | H3: 3300000 | I3: -0.255 | J3: -41.1 | K3: 71.4 | L3: 0.607 | M3: 0.66 | N3: 0.088 | O3: 0.419 | P3: 0.03 | Q3: -0.163 | R3: -0.16
A4: 38119 | B4: 46142.75 | C4: 0.429 | D4: 6.6 | E4: 15.3 | F4: 0.156 | G4: 0.006 | H4: 6000000 | I4: -0.043 | J4: -15.3 | K4: 61.5 | L4: 0.486 | M4: 0.59 | N4: 0.128 | O4: 0.356 | P4: -0.024 | Q4: 0.228 | R4: 0.021
A5: 38136 | B5: 46142.75 | C5: 0.428 | D5: 5.3 | E5: 14.9 | F5: 0.16 | G5: -0.021 | H5: 5500000 | I5: 0.016 | J5: -12.5 | K5: 74.5 | L5: 0.514 | M5: 0.63 | N5: 0.098 | O5: 0.355 | P5: -0.014 | Q5: 0.184 | R5: 0.168
A6: 38142 | B6: 46142.75 | C6: 0.103 | D6: 5.5 | E6: 13.1 | F6: 0.176 | G6: 0.011 | H6: 5200000 | I6: -0.108 | J6: -18.4 | K6: 67.3 | L6: 0.495 | M6: 0.57 | N6: 0.136 | O6: 0.356 | P6: -0.01 | Q6: 0.203 | R6: -0.008
A7: 38149 | B7: 46142.75 | C7: 0.061 | D7: 5.9 | E7: 14.6 | F7: 0.171 | G7: 0.005 | H7: 5400000 | I7: -0.068 | J7: -9.6 | K7: 71.3 | L7: 0.588 | M7: 0.61 | N7: 0.12 | O7: 0.353 | P7: -0.017 | Q7: 0.201 | R7: 0.028
A8: 38176 | B8: 46142.75 | C8: 0.432 | D8: 4.3 | E8: 10.8 | F8: 0.238 | G8: 0.092 | H8: 4700000 | I8: -0.542 | J8: -270.7 | K8: 63 | L8: 0.52 | M8: 0.62 | N8: 0.18 | O8: 0.371 | P8: 0.019 | Q8: 0.007 | R8: -0.273 | S8: 01:42 | T8: 01:24
A9: 38186 | B9: 46142.75 | C9: 0.663 | D9: 5.9 | E9: 14.2 | F9: 0.159 | G9: -0.011 | H9: 5300000 | I9: -0.083 | J9: -13.3 | K9: 82.8 | L9: 0.599 | M9: 0.72 | N9: 0.108 | O9: 0.362 | P9: -0.002 | Q9: 0.164 | R9: 0.02
A10: 38197 | B10: 46142.75 | C10: 0.201 | D10: 5.9 | E10: 14.9 | F10: 0.15 | G10: -0.06 | H10: 8100000 | I10: 0.336 | J10: -35.1 | K10: 65.6 | L10: 0.514 | M10: 0.59 | N10: 0.111 | O10: 0.349 | P10: 0.006 | Q10: 0.227 | R10: 0.038
A11: 38205 | B11: 46142.75 | C11: 0.415 | D11: 7.2 | E11: 17.1 | F11: 0.132 | G11: 0.003 | H11: 9200000 | I11: -0.081 | J11: -37.7 | K11: 62.1 | L11: 0.445 | M11: 0.53 | N11: 0.112 | O11: 0.358 | P11: 0.018 | Q11: 0.257 | R11: -0.029
A12: 38207 | B12: 46142.75 | C12: 0.339 | D12: 8.6 | E12: 18.2 | F12: 0.19 | G12: -0.003 | H12: 3900000 | I12: 0.057 | J12: -3.4 | K12: 79.7 | L12: 0.552 | M12: 0.65 | N12: 0.022 | O12: 0.355 | P12: 0.003 | Q12: 0.193 | R12: 0.04
A13: 38230 | B13: 46142.75 | C13: 0.427 | D13: 7.7 | E13: 14.1 | F13: 0.186 | G13: -0.023 | H13: 4600000 | I13: 0.115 | J13: 12.2 | K13: 66.7 | L13: 0.553 | M13: 0.67 | N13: 0.097 | O13: 0.347 | P13: -0.04 | Q13: 0.258 | R13: 0.117
A14: 38266 | B14: 46142.75 | C14: 0.46 | D14: 6.5 | E14: 16.7 | F14: 0.172 | G14: 0.008 | H14: 5200000 | I14: -0.116 | J14: -36.5 | K14: 61.1 | L14: 0.471 | M14: 0.6 | N14: 0.199 | O14: 0.419 | P14: 0.052 | Q14: 0.117 | R14: -0.063
A15: 38270 | B15: 46142.75 | C15: 0.272 | D15: 5.7 | E15: 14 | F15: 0.19 | G15: 0.01 | H15: 4300000 | I15: -0.086 | J15: -14.5 | K15: 84.1 | L15: 0.509 | M15: 0.71 | N15: 0.159 | O15: 0.364 | P15: 0.017 | Q15: 0.097 | R15: -0.025
A16: 38333 | B16: 46142.75 | C16: 0.217 | D16: 6.8 | E16: 17.4 | F16: 0.135 | G16: -0.001 | H16: 9400000 | I16: -0.085 | J16: -37.2 | K16: 62.6 | L16: 0.464 | M16: 0.6 | N16: 0.111 | O16: 0.349 | P16: -0.009 | Q16: 0.253 | R16: -0.003
A17: 38339 | B17: 46142.75 | C17: 0.296 | D17: 5.9 | E17: 15.2 | F17: 0.137 | G17: 0.01 | H17: 8300000 | I17: -0.083 | J17: -25.1 | K17: 71.2 | L17: 0.536 | M17: 0.66 | N17: 0.119 | O17: 0.353 | P17: 0.009 | Q17: 0.254 | R17: -0.013
A18: 38363 | B18: 46142.75 | C18: 0.507 | D18: 6.5 | E18: 15.5 | F18: 0.156 | G18: 0.015 | H18: 7900000 | I18: -0.036 | J18: 9.7 | K18: 66 | L18: 0.417 | M18: 0.5 | N18: 0.099 | O18: 0.342 | P18: -0.008 | Q18: 0.255 | R18: -0.007
A19: 38368 | B19: 46142.75 | C19: 0.329 | D19: 6.7 | E19: 16.1 | F19: 0.143 | G19: 0.014 | H19: 8300000 | I19: -0.102 | J19: 1.7 | K19: 68.5 | L19: 0.474 | M19: 0.62 | N19: 0.074 | O19: 0.347 | P19: -0.007 | Q19: 0.272 | R19: -0.021
A20: 38371 | B20: 46142.75 | C20: 0.282 | D20: 7.1 | E20: 18 | F20: 0.121 | G20: -0.033 | H20: 16600000 | I20: 0.182 | J20: -51.4 | K20: 64.3 | L20: 0.445 | M20: 0.58 | N20: 0.143 | O20: 0.376 | P20: 0.031 | Q20: 0.254 | R20: 0.038 | S20: 01:37 | T20: 01:42
A21: 38374 | B21: 46142.75 | C21: 0.178 | D21: 5.2 | E21: 12.5 | F21: 0.188 | G21: 0.024 | H21: 4100000 | I21: -0.109 | J21: -10.2 | K21: 68.1 | L21: 0.566 | M21: 0.65 | N21: 0.121 | O21: 0.37 | P21: -0.013 | Q21: 0.168 | R21: -0.005
A22: 38394 | B22: 46142.75 | C22: 0.023 | D22: 5.8 | E22: 12.7 | F22: 0.19 | G22: 0.004 | H22: 4300000 | I22: -0.077 | J22: -20.5 | K22: 77.7 | L22: 0.514 | M22: 0.63 | N22: 0.107 | O22: 0.401 | P22: 0.012 | Q22: 0.114 | R22: -0.024
A23: 38401 | B23: 46142.75 | C23: 0.327 | D23: 5.7 | E23: 14.9 | F23: 0.162 | G23: 0.013 | H23: 4400000 | I23: -0.088 | J23: -18.5 | K23: 89.9 | L23: 0.697 | M23: 0.75 | N23: 0.146 | O23: 0.367 | P23: -0.008 | Q23: 0.164 | R23: -0.037
A24: 38411 | B24: 46142.75 | C24: 0.171 | D24: 6.3 | E24: 16.3 | F24: 0.141 | G24: 0.014 | H24: 8500000 | I24: -0.141 | J24: -55.2 | K24: 69.7 | L24: 0.553 | M24: 0.64 | N24: 0.212 | O24: 0.368 | P24: 0.024 | Q24: 0.226 | R24: -0.055
A25: 38427 | B25: 46142.75 | C25: 0.247 | D25: 6 | E25: 14.4 | F25: 0.161 | G25: 0.022 | H25: 8200000 | I25: -0.109 | J25: -7.2 | K25: 74.1 | L25: 0.463 | M25: 0.66 | N25: 0.05 | O25: 0.338 | P25: -0.028 | Q25: 0.251 | R25: 0.056
A26: 38431 | B26: 46142.75 | C26: 0.421 | D26: 7 | E26: 17 | F26: 0.149 | G26: -0.015 | H26: 6400000 | I26: 0.005 | J26: -20.8 | K26: 71.1 | L26: 0.465 | M26: 0.66 | N26: 0.079 | O26: 0.396 | P26: 0.035 | Q26: 0.129 | R26: -0.034
A27: 38442 | B27: 46142.75 | C27: 0.558 | D27: 5.9 | E27: 15.1 | F27: 0.143 | G27: 0.007 | H27: 8600000 | I27: -0.002 | J27: -28.2 | K27: 78.8 | L27: 0.594 | M27: 0.71 | N27: 0.1 | O27: 0.35 | P27: -0.024 | Q27: 0.261 | R27: 0.03
A28: 38456 | B28: 46142.75 | C28: 0.332 | D28: 6 | E28: 15.8 | F28: 0.146 | G28: -0.014 | H28: 6300000 | I28: 0.024 | J28: -27.1 | K28: 75.2 | L28: 0.577 | M28: 0.73 | N28: 0.171 | O28: 0.351 | P28: -0.002 | Q28: 0.26 | R28: 0.028
A29: 38458 | B29: 46142.75 | C29: 0.331 | D29: 7.8 | E29: 16.7 | F29: 0.14 | G29: -0.004 | H29: 6700000 | I29: 0 | J29: -17.1 | K29: 58.5 | L29: 0.443 | M29: 0.58 | N29: 0.041 | O29: 0.378 | P29: 0.027 | Q29: 0.229 | R29: -0.026
A30: 38460 | B30: 46142.75 | C30: 0.142 | D30: 5.3 | E30: 13.4 | F30: 0.161 | G30: -0.008 | H30: 5600000 | I30: -0.002 | J30: -7.7 | K30: 80.1 | L30: 0.611 | M30: 0.64 | N30: 0.073 | O30: 0.366 | P30: 0.002 | Q30: 0.158 | R30: 0.022
A31: 38475 | B31: 46142.75 | C31: 0.703 | D31: 7 | E31: 16.9 | F31: 0.157 | G31: 0.005 | H31: 7800000 | I31: -0.055 | J31: -1.4 | K31: 65.8 | L31: 0.484 | M31: 0.56 | N31: 0.113 | O31: 0.378 | P31: -0.006 | Q31: 0.231 | R31: -0.006
A32: 38507 | B32: 46142.75 | C32: 0.559 | D32: 4.9 | E32: 11.7 | F32: 0.241 | G32: 0.056 | H32: 3500000 | I32: -0.08 | J32: -19.8 | K32: 71.8 | L32: 0.61 | M32: 0.58 | N32: 0.118 | O32: 0.388 | P32: 0.011 | Q32: 0.071 | R32: -0.06
A33: 38515 | B33: 46142.75 | C33: 0.343 | D33: 6 | E33: 16.1 | F33: 0.15 | G33: -0.016 | H33: 7200000 | I33: 0.034 | J33: 2.5 | K33: 74.2 | L33: 0.568 | M33: 0.59 | N33: 0.124 | O33: 0.374 | P33: -0.014 | Q33: 0.203 | R33: 0.026
A34: 38527 | B34: 46142.75 | C34: 0.3 | D34: 6.8 | E34: 16.7 | F34: 0.129 | G34: -0.065 | H34: 12700000 | I34: 0.419 | J34: -4.5 | K34: 52.5 | L34: 0.392 | M34: 0.47 | N34: 0.079 | O34: 0.355 | P34: 0.02 | Q34: 0.298 | R34: 0.046 | S34: 01:25 | T34: 01:21
A35: 38529 | B35: 46142.75 | C35: 0.295 | D35: 6.5 | E35: 16.7 | F35: 0.139 | G35: -0.002 | H35: 7600000 | I35: -0.079 | J35: -25.4 | K35: 67.8 | L35: 0.491 | M35: 0.58 | N35: 0.061 | O35: 0.377 | P35: 0.01 | Q35: 0.257 | R35: -0.006
A36: 38535 | B36: 46142.75 | C36: 0.82 | D36: 6.6 | E36: 15.7 | F36: 0.14 | G36: 0.007 | H36: 14000000 | I36: -0.05 | J36: 22.3 | K36: 51.2 | L36: 0.477 | M36: 0.5 | N36: 0.127 | O36: 0.33 | P36: -0.039 | Q36: 0.312 | R36: 0.025 | S36: 01:13 | T36: 01:27
A37: 38546 | B37: 46142.75 | C37: 0.23 | D37: 6.8 | E37: 16.3 | F37: 0.144 | G37: 0 | H37: 8500000 | I37: -0.037 | J37: -42 | K37: 67.2 | L37: 0.526 | M37: 0.57 | N37: 0.13 | O37: 0.356 | P37: -0.022 | Q37: 0.242 | R37: 0.101
A38: 38561 | B38: 46142.75 | C38: 0.498 | D38: 7.1 | E38: 15.6 | F38: 0.142 | G38: 0.005 | H38: 9000000 | I38: -0.072 | J38: -29.9 | K38: 59.9 | L38: 0.448 | M38: 0.56 | N38: 0.058 | O38: 0.349 | P38: -0.004 | Q38: 0.241 | R38: 0.003
A39: 38590 | B39: 46142.75 | C39: 0.269 | D39: 6.4 | E39: 14.5 | F39: 0.144 | G39: 0.009 | H39: 7600000 | I39: -0.121 | J39: -8.4 | K39: 67.3 | L39: 0.515 | M39: 0.59 | N39: 0.076 | O39: 0.339 | P39: -0.012 | Q39: 0.256 | R39: -0.005
A40: 38604 | B40: 46142.75 | C40: 0.237 | D40: 5.8 | E40: 15.2 | F40: 0.145 | G40: 0.017 | H40: 8100000 | I40: -0.169 | J40: -55.8 | K40: 81.4 | L40: 0.64 | M40: 0.65 | N40: 0.086 | O40: 0.363 | P40: -0.002 | Q40: 0.224 | R40: -0.047
...

Sheet Catalogos
A1: DM | B1: Cobertura | C1: Formato | D1: Formato Comercial | E1: Tier | F1: Activa
A2: Enrique César | B2: Ciudad De México | C2: Cafe | D2: Education | E2: C1 | F2: No
A3: Nancy Rodríguez | B3: Estado De México | C3: Drive_Thru | D3: Health Care | E3: C2 | F3: Sí
A4: Vanessa Carreño | C4: Kiosko | D4: Highway
A5: Veronica García | D5: Hypermarket
A6: Yazmin Chabela | D6: Main Avenues
A7: Yazmin García | D7: Mall
D8: Neighborhood
D9: Shopping Center
D10: Street
D11: Train & Bus Stations

Sheet Validacion
A1: VALIDACIÓN DEL CMS
A4: Control | B4: Resultado
A5: Ubicaciones capturadas | B5: =COUNTA(Ubicaciones!$A$2:$A$501) -> 72
A6: Indicadores capturados | B6: =COUNTA(Indicadores!$A$2:$A$501) -> 72
A7: CC duplicados en Ubicaciones | B7: =COUNTIF(C14:C513,"DUPLICADO") -> 0
A8: CC sin fila de Indicadores | B8: =COUNTIF(B14:B513,"FALTA") -> 428
A10: La carga en Python vuelve a ejecutar estas validaciones y además comprueba encabezados, coordenadas y relación entre ambas pestañas.
A13: CC Ubicación | B13: En Indicadores | C13: Duplicado Ubicación
A14: =Ubicaciones!A2 -> 38401 | B14: =IF(A14="","",IF(COUNTIF(Indicadores!$A$2:$A$501,A14)=0,"FALTA","OK")) -> OK | C14: =IF(A14="","",IF(COUNTIF(Ubicaciones!$A$2:$A$501,A14)>1,"DUPLICADO","OK")) -> OK
A15: =Ubicaciones!A3 -> 38604 | B15: =IF(A15="","",IF(COUNTIF(Indicadores!$A$2:$A$501,A15)=0,"FALTA","OK")) -> OK | C15: =IF(A15="","",IF(COUNTIF(Ubicaciones!$A$2:$A$501,A15)>1,"DUPLICADO","OK")) -> OK
A16: =Ubicaciones!A4 -> 43193 | B16: =IF(A16="","",IF(COUNTIF(Indicadores!$A$2:$A$501,A16)=0,"FALTA","OK")) -> OK | C16: =IF(A16="","",IF(COUNTIF(Ubicaciones!$A$2:$A$501,A16)>1,"DUPLICADO","OK")) -> OK
A17: =Ubicaciones!A5 -> 38333 | B17: =IF(A17="","",IF(COUNTIF(Indicadores!$A$2:$A$501,A17)=0,"FALTA","OK")) -> OK | C17: =IF(A17="","",IF(COUNTIF(Ubicaciones!$A$2:$A$501,A17)>1,"DUPLICADO","OK")) -> OK
A18: =Ubicaciones!A6 -> 38368 | B18: =IF(A18="","",IF(COUNTIF(Indicadores!$A$2:$A$501,A18)=0,"FALTA","OK")) -> OK | C18: =IF(A18="","",IF(COUNTIF(Ubicaciones!$A$2:$A$501,A18)>1,"DUPLICADO","OK")) -> OK
A19: =Ubicaciones!A7 -> 38515 | B19: =IF(A19="","",IF(COUNTIF(Indicadores!$A$2:$A$501,A19)=0,"FALTA","OK")) -> OK | C19: =IF(A19="","",IF(COUNTIF(Ubicaciones!$A$2:$A$501,A19)>1,"DUPLICADO","OK")) -> OK
A20: =Ubicaciones!A8 -> 38456 | B20: =IF(A20="","",IF(COUNTIF(Indicadores!$A$2:$A$501,A20)=0,"FALTA","OK")) -> OK | C20: =IF(A20="","",IF(COUNTIF(Ubicaciones!$A$2:$A$501,A20)>1,"DUPLICADO","OK")) -> OK
A21: =Ubicaciones!A9 -> 38339 | B21: =IF(A21="","",IF(COUNTIF(Indicadores!$A$2:$A$501,A21)=0,"FALTA","OK")) -> OK | C21: =IF(A21="","",IF(COUNTIF(Ubicaciones!$A$2:$A$501,A21)>1,"DUPLICADO","OK")) -> OK
A22: =Ubicaciones!A10 -> 38862 | B22: =IF(A22="","",IF(COUNTIF(Indicadores!$A$2:$A$501,A22)=0,"FALTA","OK")) -> OK | C22: =IF(A22="","",IF(COUNTIF(Ubicaciones!$A$2:$A$501,A22)>1,"DUPLICADO","OK")) -> OK
A23: =Ubicaciones!A11 -> 38186 | B23: =IF(A23="","",IF(COUNTIF(Indicadores!$A$2:$A$501,A23)=0,"FALTA","OK")) -> OK | C23: =IF(A23="","",IF(COUNTIF(Ubicaciones!$A$2:$A$501,A23)>1,"DUPLICADO","OK")) -> OK
A24: =Ubicaciones!A12 -> 38894 | B24: =IF(A24="","",IF(COUNTIF(Indicadores!$A$2:$A$501,A24)=0,"FALTA","OK")) -> OK | C24: =IF(A24="","",IF(COUNTIF(Ubicaciones!$A$2:$A$501,A24)>1,"DUPLICADO","OK")) -> OK
A25: =Ubicaciones!A13 -> 38230 | B25: =IF(A25="","",IF(COUNTIF(Indicadores!$A$2:$A$501,A25)=0,"FALTA","OK")) -> OK | C25: =IF(A25="","",IF(COUNTIF(Ubicaciones!$A$2:$A$501,A25)>1,"DUPLICADO","OK")) -> OK
... A513: =Ubicaciones!A501 -> 0 | B513: =IF(A513="","",IF(COUNTIF(Indicadores!$A$2:$A$501,A513)=0,"FALTA","OK")) -> FALTA | C513: =IF(A513="","",IF(COUNTIF(Ubicaciones!$A$2:$A$501,A513)>1,"DUPLICADO","OK")) -> OK
